Workbook

Sheet Sheet1
A1: =_xll.TR("SCREEN(U(IN(Equity(active,public,primary))/*UNV:Public*/), IN(TR.ExchangeMarketIdCode,""HSTC"",""XSTC""), CURN=USD)","TR.CommonName;TR.ExchangeName;TR.GICSIndustry;TR.GICSSector;TR.CompanyPublicSinceDate","curn=USD RH=In CH=Fd") -> Updated at 14:09:47 | B1: Company Common Name | C1: Exchange Name | D1: GICS Industry Name | E1: GICS Sector Name | F1: Date Became Public
A2: CHP.HM | B2: Central Hydropower JSC | C2: Ho Chi Minh Securities Trading Centre | D2: Independent Power and Renewable Electricity Producers | E2: Utilities | F2: 40288
A3: V21.HN | B3: Vinaconex 21 JSC | C3: Hanoi Stock Exchange | D3: Construction & Engineering | E3: Industrials | F3: 40289
A4: LIG.HN | B4: Licogi 13 JSC | C4: Hanoi Stock Exchange | D4: Construction & Engineering | E4: Industrials | F4: 40290
A5: MCC.HN | B5: High Grade Brick Tile Corp | C5: Hanoi Stock Exchange | D5: Construction Materials | E5: Materials | F5: 40294
A6: TET.HN | B6: Northern Textiles And Garments JSC | C6: Hanoi Stock Exchange | D6: Textiles, Apparel & Luxury Goods | E6: Consumer Discretionary | F6: 40296
A7: KSD.HN | B7: DNA Investment Joint Stock Corp | C7: Hanoi Stock Exchange | D7: Construction Materials | E7: Materials | F7: 40296
A8: NBW.HN | B8: Nha Be Water Supply JSC | C8: Hanoi Stock Exchange | D8: Water Utilities | E8: Utilities | F8: 43053
A9: TDC.HM | B9: Binh Duong Trade and Development JSC | C9: Ho Chi Minh Securities Trading Centre | D9: Real Estate Management & Development | E9: Real Estate | F9: 40302
A10: OGC.HM | B10: Ocean Group JSC | C10: Ho Chi Minh Securities Trading Centre | D10: Financial Services | E10: Financials | F10: 40302
A11: HTC.HN | B11: HocMon Trade JSC | C11: Hanoi Stock Exchange | D11: Oil, Gas & Consumable Fuels | E11: Energy | F11: 40305
A12: NVT.HM | B12: Ninh Van Bay Travel Real Estate JSC | C12: Ho Chi Minh Securities Trading Centre | D12: Real Estate Management & Development | E12: Real Estate | F12: 40305
A13: VCM.HN | B13: BV Life JSC | C13: Hanoi Stock Exchange | D13: Professional Services | E13: Industrials | F13: 40309
... A696: TCX.HM | B696: Techcom Securities JSC | C696: Ho Chi Minh Securities Trading Centre | D696: Capital Markets | E696: Financials | F696: 45951

Sheet Sheet2
A1: 43831
A2: 45966

Sheet YjRmYjVhNDgtMzdkMC00ZT
D3: AuditId=69734_107403491_STD_C66815C1-4A2B-4993-9493-C1F5453D23CA
D4: AuditId=82349_107403491_STD_9B7E228C-30CC-47A9-BF23-D89134DA4202
D5: AuditId=92481_107403491_STD_C1A1EB2F-8C68-4AFC-B7DB-C388BB41A9D4
D6: AuditId=59561940_107403491_STD_B94F5566-D734-4E4D-B3F0-2114155A5E1C
D7: AuditId=172268023_107403491_STD_B5470D9B-4C75-47BD-A598-1D30707F6D8A
D8: AuditId=192614852_107403491_STD_E565C324-8850-4FD0-B46D-2B9F69081D57
D9: AuditId=84516_107393580_STD_76DC990E-8B41-474E-80E2-19FA65173E0D
D10: AuditId=96235_107393580_STD_4584CB4A-AD7A-40A7-936A-AF5C3F599EBE
D11: AuditId=109071_107393580_STD_6C5750DE-DE26-45FE-B414-E983390575C6
D12: AuditId=118669_107393580_STD_8188729F-1D90-4755-A9D9-80055338A825
D13: AuditId=128315_107393580_STD_CBF8EFB9-56F4-444B-B436-B0CD02DCA05A
D14: AuditId=137904_107393580_STD_6B491C50-4574-46A5-AAB6-631899E467AB
... D4137: AuditId=1711_117098222_STD_B19BFE22-CAD3-466D-A384-948696FCA09A

Sheet Sheet3
A1: =_xll.RDP.Data(Sheet1!$A$2:$A$696,"TR.F.TotAssets","Period=FY0 Frq=FY SDate=#1 EDate=#2 CH=Fd RH=IN;periodenddate",B2,Sheet2!$A$1,Sheet2!$A$2) -> Updated at 14:22:46
D2: Total Assets
B3: CHP.HM | C3: 43830 | D3: 3611672910985
B4: CHP.HM | C4: 44196 | D4: 3532764723607
B5: CHP.HM | C5: 44561 | D5: 3272703458543
B6: CHP.HM | C6: 44926 | D6: 3259700449355
B7: CHP.HM | C7: 45291 | D7: 2967231114351
B8: CHP.HM | C8: 45657 | D8: 2696249961096
B9: V21.HN | C9: 43830 | D9: 414806519320
B10: V21.HN | C10: 44196 | D10: 437640548364
B11: V21.HN | C11: 44561 | D11: 335579886720
B12: V21.HN | C12: 44926 | D12: 317114172544
B13: V21.HN | C13: 45291 | D13: 323444750092
B14: V21.HN | C14: 45657 | D14: 365893379065
... B592: JVC.HM | C592: 44286 | D592: 627726330828
B593: JVC.HM | C593: 44926 | D593: NULL
B594: JVC.HM | C594: 44926 | D594: NULL
B595: JVC.HM | C595: 45291 | D595: 686676856095
B596: JVC.HM | C596: 45657 | D596: 828102672175
B597: PTB.HM | C597: 43830 | D597: 4328694369097
B598: PTB.HM | C598: 44196 | D598: 4773757358132
B599: PTB.HM | C599: 44561 | D599: 5430878287077
B600: PTB.HM | C600: 44926 | D600: 5238297875783
B601: PTB.HM | C601: 45291 | D601: 5263776311415
B602: PTB.HM | C602: 45657 | D602: 5489132951980
B603: CIG.HM | C603: 43830 | D603: 897151888608
B604: CIG.HM | C604: 44196 | D604: 687011930094
B605: CIG.HM | C605: 44561 | D605: 707502590681
B606: CIG.HM | C606: 44926 | D606: 729551648070
... B1685: ICT.HM | C1685: 45657 | D1685: 1475380141521
B1686: NO1.HM | D1686: Unable to collect data for the field 'TR.F.TotAssets' and some specific identifier(s).
B1687: PCH.HN | C1687: 43830 | D1687: 175641839663
B1688: PCH.HN | C1688: 44196 | D1688: 213749477804
B1689: PCH.HN | C1689: 44561 | D1689: 233655716736
B1690: PCH.HN | C1690: 44926 | D1690: 257234571546
B1691: PCH.HN | C1691: 45291 | D1691: 270339071591
B1692: PCH.HN | C1692: 45657 | D1692: 283620919180
B1693: DVM.HN | C1693: 44196 | D1693: 820855245958
B1694: DVM.HN | C1694: 44561 | D1694: 1032942899927
B1695: DVM.HN | C1695: 44926 | D1695: 1359265929276
...

Sheet NTlmNTAxMGUtMWJkNS00Nz
D3: AuditId=69791_107403491_STD_2CAC842F-913C-485B-B189-B8874EA69354
D4: AuditId=82415_107403491_STD_9BF32382-3105-42E3-862E-9A4D9DE0A102
D5: AuditId=92562_107403491_STD_C47DB7CF-D369-441F-AC2A-9A5B6571A578
D6: AuditId=59562040_107403491_STD_B94F5566-D734-4E4D-B3F0-2114155A5E1C
D7: AuditId=172268127_107403491_STD_B5470D9B-4C75-47BD-A598-1D30707F6D8A
D8: AuditId=192614935_107403491_STD_E565C324-8850-4FD0-B46D-2B9F69081D57
D9: AuditId=84584_107393580_STD_76DC990E-8B41-474E-80E2-19FA65173E0D
D10: AuditId=96303_107393580_STD_D11D48E2-E642-4D48-9003-18FBF7ED8119
D11: AuditId=109167_107393580_STD_6C5750DE-DE26-45FE-B414-E983390575C6
D12: AuditId=118742_107393580_STD_8188729F-1D90-4755-A9D9-80055338A825
D13: AuditId=128383_107393580_STD_CBF8EFB9-56F4-444B-B436-B0CD02DCA05A
D14: AuditId=137964_107393580_STD_6B491C50-4574-46A5-AAB6-631899E467AB
... D3982: AuditId=1820_117098222_STD_B19BFE22-CAD3-466D-A384-948696FCA09A

Sheet Sheet5
A1: =_xll.RDP.Data(Sheet1!$A$2:$A$696,"TR.F.TotCurrLiab","Period=FY0 Frq=FY SDate=#1 EDate=#2 CH=Fd RH=IN;periodenddate",B2,Sheet2!$A$1,Sheet2!$A$2) -> Updated at 14:23:09
D2: Total Current Liabilities
B3: CHP.HM | C3: 43830 | D3: 441506514704
B4: CHP.HM | C4: 44196 | D4: 376922719745
B5: CHP.HM | C5: 44561 | D5: 325325368538
B6: CHP.HM | C6: 44926 | D6: 458135420679
B7: CHP.HM | C7: 45291 | D7: 433121421760
B8: CHP.HM | C8: 45657 | D8: 321564471202
B9: V21.HN | C9: 43830 | D9: 299141323687
B10: V21.HN | C10: 44196 | D10: 281427582779
B11: V21.HN | C11: 44561 | D11: 188845815222
B12: V21.HN | C12: 44926 | D12: 174960379061
B13: V21.HN | C13: 45291 | D13: 181715224555
B14: V21.HN | C14: 45657 | D14: 224883909674
... B302: SHP.HM | C302: 45657 | D302: 105775522508
B303: NVB.HN | D303: NULL
B304: PTL.HM | C304: 43830 | D304: 369186744962
B305: PTL.HM | C305: 44196 | D305: 398568412145
B306: PTL.HM | C306: 44561 | D306: 300683928638
B307: PTL.HM | C307: 44926 | D307: 137575553242
B308: PTL.HM | C308: 45291 | D308: 140281598495
B309: PTL.HM | C309: 45657 | D309: 597128848166
B310: HVX.HM | C310: 43830 | D310: 269061885523
B311: HVX.HM | C311: 44196 | D311: 312348071526
B312: HVX.HM | C312: 44561 | D312: 308093966749
B313: HVX.HM | C313: 44926 | D313: 327653679852
B314: HVX.HM | C314: 45291 | D314: 315858806833
B315: HVX.HM | C315: 45657 | D315: 267598746210
... B549: D11.HN | C549: 45657 | D549: 154970593808
B550: PTI.HN | D550: NULL
B551: CCL.HM | C551: 43830 | D551: 348980525491
B552: CCL.HM | C552: 44196 | D552: 468156648089
B553: CCL.HM | C553: 44561 | D553: 500184170503
B554: CCL.HM | C554: 44926 | D554: 511573094915
B555: CCL.HM | C555: 45291 | D555: 256612543477
B556: CCL.HM | C556: 45657 | D556: 276933522264
B557: C47.HM | C557: 43830 | D557: 1094274594254
B558: C47.HM | C558: 44196 | D558: 992932767542
B559: C47.HM | C559: 44561 | D559: 811501480617
B560: C47.HM | C560: 44926 | D560: 886933657193
...

Sheet ODBjNjhlNDEtMzU2Yy00MG

Sheet NGFkZGMwODUtN2E2OC00N2
D3: AuditId=69784_107403491_STD_3963666A-6824-4AF6-AECA-B62E2BA4D479
D4: AuditId=82406_107403491_STD_9B7E228C-30CC-47A9-BF23-D89134DA4202
D5: AuditId=92538_107403491_STD_C1A1EB2F-8C68-4AFC-B7DB-C388BB41A9D4
D6: AuditId=59562009_107403491_STD_B94F5566-D734-4E4D-B3F0-2114155A5E1C
D7: AuditId=172268099_107403491_STD_B5470D9B-4C75-47BD-A598-1D30707F6D8A
D8: AuditId=192614916_107403491_STD_E565C324-8850-4FD0-B46D-2B9F69081D57
D9: AuditId=84577_107393580_STD_76DC990E-8B41-474E-80E2-19FA65173E0D
D10: AuditId=96297_107393580_STD_4584CB4A-AD7A-40A7-936A-AF5C3F599EBE
D11: AuditId=109136_107393580_STD_6C5750DE-DE26-45FE-B414-E983390575C6
D12: AuditId=118715_107393580_STD_8188729F-1D90-4755-A9D9-80055338A825
D13: AuditId=128357_107393580_STD_CBF8EFB9-56F4-444B-B436-B0CD02DCA05A
D14: AuditId=137954_107393580_STD_04E438C3-0EEB-40CE-974A-6D0816599776
... D4137: AuditId=1804_117098222_STD_B19BFE22-CAD3-466D-A384-948696FCA09A

Sheet Sheet7
A1: =_xll.RDP.Data(Sheet1!$A$2:$A$696,"TR.EPSMean","Period=FY0 Frq=FY SDate=#1 EDate=#2 CH=Fd RH=IN;periodenddate",B2,Sheet2!$A$1,Sheet2!$A$2) -> Updated at 14:23:26
D2: Earnings Per Share - Mean
B3: CHP.HM | D3: NULL
B4: V21.HN | D4: NULL
B5: LIG.HN | D5: NULL
B6: MCC.HN | D6: NULL
B7: TET.HN | D7: NULL
B8: KSD.HN | D8: NULL
B9: NBW.HN | D9: NULL
B10: TDC.HM | D10: NULL
B11: OGC.HM | D11: NULL
B12: HTC.HN | D12: NULL
B13: NVT.HM | D13: NULL
B14: VCM.HN | D14: NULL
... B18: HU1.HM | D18: NULL
B19: SBA.HM | C19: 43830 | D19: 1.375
B20: IDV.HN | D20: NULL
B21: AME.HN | D21: NULL
B22: DTL.HM | D22: NULL
B23: GDW.HN | D23: NULL
B24: PDN.HM | D24: NULL
B25: NNC.HM | D25: NULL
B26: DLG.HM | D26: NULL
B27: CMV.HM | D27: NULL
B28: VE3.HN | D28: NULL
B29: BCE.HM | D29: NULL
B30: DC2.HN | D30: NULL
B31: ORS.HM | D31: NULL
... B33: NHA.HM | D33: NULL
B34: AAA.HM | C34: 43830 | D34: 2110.8228
B35: AAA.HM | C35: 44196 | D35: 1664.5456
B36: AAA.HM | C36: 44561 | D36: 942
B37: AAA.HM | C37: 45291 | D37: 711
B38: HBS.HN | D38: NULL
B39: LDP.HN | D39: NULL
B40: DRH.HM | D40: NULL
B41: PSI.HN | D41: NULL
B42: SMT.HN | D42: NULL
B43: VRC.HM | D43: NULL
B44: HMH.HN | D44: NULL
...

Sheet Sheet9
A1: =_xll.RDP.Data(Sheet1!$A$2:$A$696,"TR.F.ComEqTot","Period=FY0 Frq=FY SDate=#1 EDate=#2 CH=Fd RH=IN;periodenddate",B2,Sheet2!$A$1,Sheet2!$A$2) -> Updated at 14:27:11
D2: Common Equity - Total
B3: CHP.HM | C3: 43830 | D3: 1764242810870
B4: CHP.HM | C4: 44196 | D4: 1893861790283
B5: CHP.HM | C5: 44561 | D5: 1894194143805
B6: CHP.HM | C6: 44926 | D6: 1997177349845
B7: CHP.HM | C7: 45291 | D7: 1938518281144
B8: CHP.HM | C8: 45657 | D8: 1987895836165
B9: V21.HN | C9: 43830 | D9: 115665195633
B10: V21.HN | C10: 44196 | D10: 117203737081
B11: V21.HN | C11: 44561 | D11: 120917661403
B12: V21.HN | C12: 44926 | D12: 121846546191
B13: V21.HN | C13: 45291 | D13: 121905554149
B14: V21.HN | C14: 45657 | D14: 120729487924
... B592: JVC.HM | C592: 44286 | D592: 454692353573
B593: JVC.HM | C593: 44926 | D593: NULL
B594: JVC.HM | C594: 44926 | D594: NULL
B595: JVC.HM | C595: 45291 | D595: 499149237891
B596: JVC.HM | C596: 45657 | D596: 539431468685
B597: PTB.HM | C597: 43830 | D597: 1784503605222
B598: PTB.HM | C598: 44196 | D598: 1922878997099
B599: PTB.HM | C599: 44561 | D599: 2320430347266
B600: PTB.HM | C600: 44926 | D600: 2687241541830
B601: PTB.HM | C601: 45291 | D601: 2723503357061
B602: PTB.HM | C602: 45657 | D602: 2903296701880
B603: CIG.HM | C603: 43830 | D603: 203400328673
B604: CIG.HM | C604: 44196 | D604: 27617307756
B605: CIG.HM | C605: 44561 | D605: 43311840474
B606: CIG.HM | C606: 44926 | D606: 33959901357
... B1685: ICT.HM | C1685: 45657 | D1685: 656220180343
B1686: NO1.HM | D1686: Unable to collect data for the field 'TR.F.ComEqTot' and some specific identifier(s).
B1687: PCH.HN | C1687: 43830 | D1687: 148503144757
B1688: PCH.HN | C1688: 44196 | D1688: 185910049438
B1689: PCH.HN | C1689: 44561 | D1689: 190426392294
B1690: PCH.HN | C1690: 44926 | D1690: 233406045406
B1691: PCH.HN | C1691: 45291 | D1691: 245196649553
B1692: PCH.HN | C1692: 45657 | D1692: 257604910879
B1693: DVM.HN | C1693: 44196 | D1693: 211557638624
B1694: DVM.HN | C1694: 44561 | D1694: 440622348826
B1695: DVM.HN | C1695: 44926 | D1695: 648230535183
...

Sheet NjU0Zjc4OGEtYmJhYi00ZT
D3: AuditId=69788_107403491_STD_C66815C1-4A2B-4993-9493-C1F5453D23CA
D4: AuditId=82413_107403491_STD_9B7E228C-30CC-47A9-BF23-D89134DA4202
D5: AuditId=92546_107403491_STD_C1A1EB2F-8C68-4AFC-B7DB-C388BB41A9D4
D6: AuditId=59562022_107403491_STD_B94F5566-D734-4E4D-B3F0-2114155A5E1C
D7: AuditId=172268091_107403491_STD_B5470D9B-4C75-47BD-A598-1D30707F6D8A
D8: AuditId=192614913_107403491_STD_E565C324-8850-4FD0-B46D-2B9F69081D57
D9: AuditId=84582_107393580_STD_76DC990E-8B41-474E-80E2-19FA65173E0D
D10: AuditId=96301_107393580_STD_4584CB4A-AD7A-40A7-936A-AF5C3F599EBE
D11: AuditId=109147_107393580_STD_6C5750DE-DE26-45FE-B414-E983390575C6
D12: AuditId=118720_107393580_STD_8188729F-1D90-4755-A9D9-80055338A825
D13: AuditId=129800_107393580_STD_802F3819-F939-4EFD-9F53-5A4BAD1B7C0D
D15: AuditId=87182_107345512_STD_7B8F1745-6942-46B4-BA25-8101F8D58C43
... D3482: AuditId=1792_117098222_STD_B19BFE22-CAD3-466D-A384-948696FCA09A

Sheet Sheet11
A1: =_xll.RDP.Data(Sheet1!$A$2:$A$696,"TR.F.DebtLTTot","Period=FY0 Frq=FY SDate=#1 EDate=#2 CH=Fd RH=IN;periodenddate",B2,Sheet2!$A$1,Sheet2!$A$2) -> Updated at 14:29:33
D2: Debt - Long-Term - Total
B3: CHP.HM | C3: 43830 | D3: 1405923585411
B4: CHP.HM | C4: 44196 | D4: 1261980213579
B5: CHP.HM | C5: 44561 | D5: 1053183946200
B6: CHP.HM | C6: 44926 | D6: 804387678831
B7: CHP.HM | C7: 45291 | D7: 595591411447
B8: CHP.HM | C8: 45657 | D8: 386789653729
B9: V21.HN | C9: 43830 | D9: 0
B10: V21.HN | C10: 44196 | D10: 25296681191
B11: V21.HN | C11: 44561 | D11: 5450899401
B12: V21.HN | C12: 44926 | D12: 0
B13: V21.HN | C13: 45291 | D13: 0
B14: V21.HN | C14: 45657 | D14: NULL
B15: LIG.HN | C15: 43830 | D15: 936187832416
B16: LIG.HN | C16: 44196 | D16: 969126200879
B17: LIG.HN | C17: 44561 | D17: 415034023563
B18: LIG.HN | C18: 44926 | D18: 716910955913
B19: LIG.HN | C19: 45291 | D19: 874333144747
B20: LIG.HN | C20: 45657 | D20: 827364761746
B21: MCC.HN | D21: NULL
B22: TET.HN | D22: NULL
B23: KSD.HN | D23: NULL
B24: NBW.HN | D24: NULL
B25: TDC.HM | C25: 43830 | D25: 317479278638
B26: TDC.HM | C26: 44196 | D26: 861867141342
B27: TDC.HM | C27: 44561 | D27: 801192893344
B28: TDC.HM | C28: 44926 | D28: 687423183336
B29: TDC.HM | C29: 45291 | D29: 689685706000
B30: TDC.HM | C30: 45657 | D30: 152642153587
B31: OGC.HM | C31: 43830 | D31: 160031166911
B32: OGC.HM | C32: 44196 | D32: 153301588029
B33: OGC.HM | C33: 44561 | D33: 151231166911
B34: OGC.HM | C34: 44926 | D34: 132331166911
B35: OGC.HM | C35: 45291 | D35: 1532331166911
B36: OGC.HM | C36: 45657 | D36: 1270000000000
B37: HTC.HN | D37: NULL
B38: NVT.HM | C38: 43830 | D38: 8325135038
B39: NVT.HM | C39: 44196 | D39: 2775043530
B40: NVT.HM | C40: 44561 | D40: 295117064809
...

Sheet ZmIzNmI3MDAtYWMzOC00MD
D3: AuditId=69749_107403491_STD_2CAC842F-913C-485B-B189-B8874EA69354
D4: AuditId=82371_107403491_STD_9BF32382-3105-42E3-862E-9A4D9DE0A102
D5: AuditId=92496_107403491_STD_C47DB7CF-D369-441F-AC2A-9A5B6571A578
D6: AuditId=59561973_107403491_STD_B94F5566-D734-4E4D-B3F0-2114155A5E1C
D7: AuditId=172268053_107403491_STD_B5470D9B-4C75-47BD-A598-1D30707F6D8A
D8: AuditId=192614871_107403491_STD_6C81D584-74D2-4A8C-8F9B-51699DB4BAA3
D9: AuditId=84539_107393580_STD_76DC990E-8B41-474E-80E2-19FA65173E0D
D10: AuditId=96263_107393580_STD_4584CB4A-AD7A-40A7-936A-AF5C3F599EBE
D11: AuditId=109108_107393580_STD_6C5750DE-DE26-45FE-B414-E983390575C6
D12: AuditId=118678_107393580_STD_8188729F-1D90-4755-A9D9-80055338A825
D13: AuditId=128327_107393580_STD_CBF8EFB9-56F4-444B-B436-B0CD02DCA05A
D14: AuditId=137910_107393580_STD_6B491C50-4574-46A5-AAB6-631899E467AB
... D3842: AuditId=1745_117098222_STD_B19BFE22-CAD3-466D-A384-948696FCA09A

Sheet Sheet13
A1: =_xll.RDP.Data(Sheet1!$A$2:$A$696,"TR.F.TradeAcctPbleAccrualsST","Period=FY0 Frq=FY SDate=#1 EDate=#2 CH=Fd RH=IN;periodenddate",B2,Sheet2!$A$1,Sheet2!$A$2) -> Updated at 14:32:18
D2: Trade Accounts Payable & Accruals - Short-Term
B3: CHP.HM | C3: 43830 | D3: 152453331212
B4: CHP.HM | C4: 44196 | D4: 45031975861
B5: CHP.HM | C5: 44561 | D5: 45260147855
B6: CHP.HM | C6: 44926 | D6: 40179336132
B7: CHP.HM | C7: 45291 | D7: 31274389649
B8: CHP.HM | C8: 45657 | D8: 36576084146
B9: V21.HN | C9: 43830 | D9: 125748551385
B10: V21.HN | C10: 44196 | D10: 162451579136
B11: V21.HN | C11: 44561 | D11: 69951315149
B12: V21.HN | C12: 44926 | D12: 62950374533
B13: V21.HN | C13: 45291 | D13: 35139737704
B14: V21.HN | C14: 45657 | D14: 54375232741
... B170: DC2.HN | C170: 45657 | D170: 60895556389
B171: ORS.HM | D171: NULL
B172: DTA.HM | C172: 43830 | D172: 2560715224
B173: DTA.HM | C173: 44196 | D173: 7634463134
B174: DTA.HM | C174: 44561 | D174: 5582035554
B175: DTA.HM | C175: 44926 | D175: 50817520184
B176: DTA.HM | C176: 45291 | D176: 22401246574
B177: DTA.HM | C177: 45657 | D177: 35642608615
B178: NHA.HM | C178: 43830 | D178: 823713347
B179: NHA.HM | C179: 44196 | D179: 25372746087
B180: NHA.HM | C180: 44561 | D180: 60746639738
B181: NHA.HM | C181: 44926 | D181: 48393255675
B182: NHA.HM | C182: 45291 | D182: 22641273245
B183: NHA.HM | C183: 45657 | D183: 24735678292
... B189: AAA.HM | C189: 45657 | D189: 1066295003739
B190: HBS.HN | D190: NULL
B191: LDP.HN | C191: 43830 | D191: 73944058401
B192: LDP.HN | C192: 44196 | D192: 45806752606
B193: LDP.HN | C193: 44561 | D193: 17308835666
B194: LDP.HN | C194: 44926 | D194: 39051027368
B195: LDP.HN | C195: 45291 | D195: 31883324170
B196: LDP.HN | C196: 45657 | D196: 47279590934
B197: DRH.HM | C197: 43830 | D197: 75681486174
B198: DRH.HM | C198: 44196 | D198: 93162670560
B199: DRH.HM | C199: 44561 | D199: 184117921585
B200: DRH.HM | C200: 44926 | D200: 224193766998
...

Sheet N2IzMDU2YzktYTdhYS00YW
D5: AuditId=87135_107345512_STD_7B8F1745-6942-46B4-BA25-8101F8D58C43
D6: AuditId=100296_107345512_STD_C335E499-4FAD-4A3C-BEE3-7E40058F9E0E
D7: AuditId=115210_107345512_STD_EC5F40F5-6786-4665-AEFA-A17A2C0BEB2F
D8: AuditId=126052_107345512_STD_C5C6F882-0625-4D02-8D51-B637A286169C
D9: AuditId=137030_107345512_STD_A3689EC0-86B0-44B8-8A5D-A95202961498
D10: AuditId=148230_107345512_STD_740CA875-3E53-498F-B93C-9A2072BC6A88
D16: AuditId=115809_107408462_STD_AF3885ED-00A5-41FA-9D46-840A49F8456C
D17: AuditId=113746_107408462_STD_8C401689-43FD-49DD-86E9-4F3007BE6DE8
D18: AuditId=80559859_107408462_STD_317CECBF-6549-4EA0-94C1-1F0307CB6BB1
D19: AuditId=57915060_107408462_STD_84D91A2D-0CB4-4F49-BD26-DF05040A8CBB
D20: AuditId=167193384_107408462_STD_3C30F9C7-4855-42D7-B71B-7F29953A0B34
D21: AuditId=240869811_107408462_STD_EC49933E-D98F-44A5-B8ED-BE9B8F9995C0
... D1408: AuditId=1750_117098222_STD_B19BFE22-CAD3-466D-A384-948696FCA09A

Sheet Sheet15
A1: =_xll.RDP.Data(Sheet1!$A$2:$A$696,"TR.F.AcctPbleInclAccrExpnLT","Period=FY0 Frq=FY SDate=#1 EDate=#2 CH=Fd RH=IN;periodenddate",B2,Sheet2!$A$1,Sheet2!$A$2) -> Updated at 14:33:08
D2: Accounts Payable including Accrued Expenses - Long-Term
B3: CHP.HM | D3: NULL
B4: V21.HN | D4: NULL
B5: LIG.HN | C5: 43830 | D5: 77221962098
B6: LIG.HN | C6: 44196 | D6: 237914623985
B7: LIG.HN | C7: 44561 | D7: 282356892576
B8: LIG.HN | C8: 44926 | D8: 318343054689
B9: LIG.HN | C9: 45291 | D9: 237684594235
B10: LIG.HN | C10: 45657 | D10: 111583365094
B11: MCC.HN | D11: NULL
B12: TET.HN | D12: NULL
B13: KSD.HN | D13: NULL
B14: NBW.HN | D14: NULL
B15: TDC.HM | D15: NULL
B16: OGC.HM | C16: 43830 | D16: 41320839176
B17: OGC.HM | C17: 44196 | D17: 3922928954
B18: OGC.HM | C18: 44561 | D18: 3922928954
B19: OGC.HM | C19: 44926 | D19: 3922928954
B20: OGC.HM | C20: 45291 | D20: 3363621314
B21: OGC.HM | C21: 45657 | D21: 2625664458
B22: HTC.HN | D22: NULL
B23: NVT.HM | D23: NULL
B24: VCM.HN | D24: NULL
B25: SPM.HM | D25: NULL
B26: CX8.HN | D26: NULL
B27: TNT.HM | C27: 43830 | D27: NULL
B28: TNT.HM | C28: 44196 | D28: NULL
B29: TNT.HM | C29: 44561 | D29: NULL
B30: TNT.HM | C30: 44926 | D30: NULL
B31: TNT.HM | C31: 45291 | D31: 27271089917
B32: TNT.HM | C32: 45657 | D32: 0
B33: HU1.HM | D33: NULL
B34: SBA.HM | D34: NULL
B35: IDV.HN | D35: NULL
B36: AME.HN | C36: 43830 | D36: NULL
B37: AME.HN | C37: 44196 | D37: NULL
B38: AME.HN | C38: 44561 | D38: 0
B39: AME.HN | C39: 44926 | D39: 0
B40: AME.HN | C40: 45291 | D40: NULL
...

Sheet OWY5NTFhZjktYWIwNy00OT
D95: AuditId=87456_106151713_STD_E5AB4070-504D-49E3-B476-DD99295789AF
D96: AuditId=99770_106151713_STD_E5AB4070-504D-49E3-B476-DD99295789AF
D97: AuditId=113883_106151713_STD_F73303BB-ACF0-479D-AA05-E38063B5DFE9
D98: AuditId=124059_106151713_STD_CF8FF8A5-B18A-44BA-85A3-60B97046B7B2
D99: AuditId=136073606_106151713_STD_35A4E005-6817-47C1-A333-5ABF7F8BE98A
D100: AuditId=250813083_106151713_STD_DAA05BC2-A77E-415C-BFBE-C8E45708E001
D114: AuditId=69420_110243153_STD_58D85CC3-E754-43DF-8143-DAFEF270B813
D115: AuditId=81268_110243153_STD_9BCF2486-21E1-4012-ADBC-F60F2C314713
D116: AuditId=93299_110243153_STD_00506DA0-88A1-4689-9B72-907F0213CF5B
D117: AuditId=21516356_110243153_STD_D76DE1CF-C458-43DF-9D94-25FA7E02DA15
D118: AuditId=154415020_110243153_STD_911B972A-5735-4F84-B1E1-72B6A7B887C3
D119: AuditId=217784404_110243153_STD_622D558E-DFFE-4754-AFAF-FF244200F827
... D635: AuditId=221829730_103854723_STD_320A30A9-E799-43EE-8296-45C43C2E64E4

Sheet Sheet17
A1: =_xll.RDP.Data(Sheet1!$A$2:$A$696,"TR.F.RcvblTot","Period=FY0 Frq=FY SDate=#1 EDate=#2 CH=Fd RH=IN;periodenddate",B2,Sheet2!$A$1,Sheet2!$A$2) -> Updated at 14:34:35
D2: Receivables - Total
B3: CHP.HM | D3: NULL
B4: V21.HN | D4: NULL
B5: LIG.HN | D5: NULL
B6: MCC.HN | D6: NULL
B7: TET.HN | D7: NULL
B8: KSD.HN | D8: NULL
B9: NBW.HN | D9: NULL
B10: TDC.HM | D10: NULL
B11: OGC.HM | D11: NULL
B12: HTC.HN | D12: NULL
B13: NVT.HM | D13: NULL
B14: VCM.HN | D14: NULL
... B94: D11.HN | D94: NULL
B95: PTI.HN | C95: 43830 | D95: 936784381813
B96: PTI.HN | C96: 44196 | D96: 772343505096
B97: PTI.HN | C97: 44561 | D97: 744999838496
B98: PTI.HN | C98: 44926 | D98: 779482009172
B99: PTI.HN | C99: 45291 | D99: 677734680980
B100: PTI.HN | C100: 45657 | D100: 764139870188
B101: CCL.HM | D101: NULL
B102: C47.HM | D102: NULL
B103: DIH.HN | D103: NULL
B104: NDN.HN | D104: NULL
B105: IDI.HM | D105: NULL
B106: JVC.HM | D106: NULL
B107: PTB.HM | D107: NULL
B108: CIG.HM | D108: NULL
B109: INC.HN | D109: NULL
B110: BSI.HM | D110: NULL
B111: THG.HM | D111: NULL
B112: SVN.HN | D112: NULL
B113: IVS.HN | D113: NULL
B114: PGI.HM | C114: 43830 | D114: 571057291328
B115: PGI.HM | C115: 44196 | D115: 451875824208
B116: PGI.HM | C116: 44561 | D116: 476206031616
B117: PGI.HM | C117: 44926 | D117: 460297429868
B118: PGI.HM | C118: 45291 | D118: 623387145100
B119: PGI.HM | C119: 45657 | D119: 675498335016
...

Sheet OThmMDI2MzgtNzhmMS00OT
D3: AuditId=69792_107403491_STD_C66815C1-4A2B-4993-9493-C1F5453D23CA
D4: AuditId=82416_107403491_STD_9B7E228C-30CC-47A9-BF23-D89134DA4202
D5: AuditId=92548_107403491_STD_C1A1EB2F-8C68-4AFC-B7DB-C388BB41A9D4
D6: AuditId=59562031_107403491_STD_B94F5566-D734-4E4D-B3F0-2114155A5E1C
D7: AuditId=172268112_107403491_STD_B5470D9B-4C75-47BD-A598-1D30707F6D8A
D8: AuditId=192614928_107403491_STD_6C81D584-74D2-4A8C-8F9B-51699DB4BAA3
D9: AuditId=84585_107393580_STD_76DC990E-8B41-474E-80E2-19FA65173E0D
D10: AuditId=96304_107393580_STD_4584CB4A-AD7A-40A7-936A-AF5C3F599EBE
D11: AuditId=109151_107393580_STD_6C5750DE-DE26-45FE-B414-E983390575C6
D12: AuditId=118734_107393580_STD_8188729F-1D90-4755-A9D9-80055338A825
D13: AuditId=128370_107393580_STD_CBF8EFB9-56F4-444B-B436-B0CD02DCA05A
D14: AuditId=137958_107393580_STD_6B491C50-4574-46A5-AAB6-631899E467AB
... D4137: AuditId=1816_117098222_STD_B19BFE22-CAD3-466D-A384-948696FCA09A

Sheet Sheet19
A1: =_xll.RDP.Data(Sheet1!$A$2:$A$696,"TR.F.LoansRcvblTot","Period=FY0 Frq=FY SDate=#1 EDate=#2 CH=Fd RH=IN;periodenddate",B2,Sheet2!$A$1,Sheet2!$A$2) -> Updated at 14:36:26
D2: Loans & Receivables - Total
B3: CHP.HM | C3: 43830 | D3: 163250952675
B4: CHP.HM | C4: 44196 | D4: 176670958189
B5: CHP.HM | C5: 44561 | D5: 296555414769
B6: CHP.HM | C6: 44926 | D6: 340267950574
B7: CHP.HM | C7: 45291 | D7: 420471811517
B8: CHP.HM | C8: 45657 | D8: 302694339604
B9: V21.HN | C9: 43830 | D9: 132753319072
B10: V21.HN | C10: 44196 | D10: 114676677460
B11: V21.HN | C11: 44561 | D11: 155095782412
B12: V21.HN | C12: 44926 | D12: 163165719683
B13: V21.HN | C13: 45291 | D13: 141265655757
B14: V21.HN | C14: 45657 | D14: 153952358635
... B592: JVC.HM | C592: 44286 | D592: 152952261073
B593: JVC.HM | C593: 44926 | D593: NULL
B594: JVC.HM | C594: 44926 | D594: NULL
B595: JVC.HM | C595: 45291 | D595: 967651587397
B596: JVC.HM | C596: 45657 | D596: 80108193142
B597: PTB.HM | C597: 43830 | D597: 885008034478
B598: PTB.HM | C598: 44196 | D598: 892455155513
B599: PTB.HM | C599: 44561 | D599: 1047833389214
B600: PTB.HM | C600: 44926 | D600: 911798529570
B601: PTB.HM | C601: 45291 | D601: 984891347415
B602: PTB.HM | C602: 45657 | D602: 1242411418618
B603: CIG.HM | C603: 43830 | D603: 392488769024
B604: CIG.HM | C604: 44196 | D604: 379196437316
B605: CIG.HM | C605: 44561 | D605: 392745420331
B606: CIG.HM | C606: 44926 | D606: 504816723345
... B1685: ICT.HM | C1685: 45657 | D1685: 615475742954
B1686: NO1.HM | D1686: Unable to collect data for the field 'TR.F.LoansRcvblTot' and some specific identifier(s).
B1687: PCH.HN | C1687: 43830 | D1687: 9046099658
B1688: PCH.HN | C1688: 44196 | D1688: 7013787069
B1689: PCH.HN | C1689: 44561 | D1689: 2812823347
B1690: PCH.HN | C1690: 44926 | D1690: 25895034938
B1691: PCH.HN | C1691: 45291 | D1691: 2703275841
B1692: PCH.HN | C1692: 45657 | D1692: 16661193010
B1693: DVM.HN | C1693: 44196 | D1693: 321209899169
B1694: DVM.HN | C1694: 44561 | D1694: 318348593906
B1695: DVM.HN | C1695: 44926 | D1695: 318265702598
...

Sheet ZWJlNjk0YWEtMmE1My00MW
D3: AuditId=69762_107403491_STD_C66815C1-4A2B-4993-9493-C1F5453D23CA
D4: AuditId=82387_107403491_STD_9BF32382-3105-42E3-862E-9A4D9DE0A102
D5: AuditId=92521_107403491_STD_C1A1EB2F-8C68-4AFC-B7DB-C388BB41A9D4
D6: AuditId=59561990_107403491_STD_B94F5566-D734-4E4D-B3F0-2114155A5E1C
D7: AuditId=172268074_107403491_STD_B5470D9B-4C75-47BD-A598-1D30707F6D8A
D8: AuditId=192614888_107403491_STD_E565C324-8850-4FD0-B46D-2B9F69081D57
D9: AuditId=84551_107393580_STD_76DC990E-8B41-474E-80E2-19FA65173E0D
D10: AuditId=96276_107393580_STD_4584CB4A-AD7A-40A7-936A-AF5C3F599EBE
D11: AuditId=109119_107393580_STD_6C5750DE-DE26-45FE-B414-E983390575C6
D12: AuditId=118696_107393580_STD_8188729F-1D90-4755-A9D9-80055338A825
D13: AuditId=128341_107393580_STD_CBF8EFB9-56F4-444B-B436-B0CD02DCA05A
D14: AuditId=137922_107393580_STD_6B491C50-4574-46A5-AAB6-631899E467AB
... D4137: AuditId=1763_117098222_STD_B19BFE22-CAD3-466D-A384-948696FCA09A

Sheet Sheet21
A1: =_xll.RDP.Data(Sheet1!$A$2:$A$696,"TR.F.CashCashEquivTot","Period=FY0 Frq=FY SDate=#1 EDate=#2 CH=Fd RH=IN;periodenddate",B2,Sheet2!$A$1,Sheet2!$A$2) -> Updated at 14:40:55
D2: Cash & Cash Equivalents - Total
B3: CHP.HM | C3: 43830 | D3: 179174174566
B4: CHP.HM | C4: 44196 | D4: 269707837090
B5: CHP.HM | C5: 44561 | D5: 91038683484
B6: CHP.HM | C6: 44926 | D6: 251256101502
B7: CHP.HM | C7: 45291 | D7: 113250882968
B8: CHP.HM | C8: 45657 | D8: 197904693647
B9: V21.HN | C9: 43830 | D9: 5738770104
B10: V21.HN | C10: 44196 | D10: 5059049245
B11: V21.HN | C11: 44561 | D11: 30211112285
B12: V21.HN | C12: 44926 | D12: 3490121694
B13: V21.HN | C13: 45291 | D13: 7360520675
B14: V21.HN | C14: 45657 | D14: 14811078411
... B592: JVC.HM | C592: 44286 | D592: 120139128350
B593: JVC.HM | C593: 44926 | D593: NULL
B594: JVC.HM | C594: 44926 | D594: NULL
B595: JVC.HM | C595: 45291 | D595: 152936802760
B596: JVC.HM | C596: 45657 | D596: 19581608627
B597: PTB.HM | C597: 43830 | D597: 126518814646
B598: PTB.HM | C598: 44196 | D598: 167783353561
B599: PTB.HM | C599: 44561 | D599: 135866626171
B600: PTB.HM | C600: 44926 | D600: 272074930811
B601: PTB.HM | C601: 45291 | D601: 428337603384
B602: PTB.HM | C602: 45657 | D602: 470850849148
B603: CIG.HM | C603: 43830 | D603: 2493226527
B604: CIG.HM | C604: 44196 | D604: 2378308561
B605: CIG.HM | C605: 44561 | D605: 916253049
B606: CIG.HM | C606: 44926 | D606: 979933550
... B1685: ICT.HM | C1685: 45657 | D1685: 429629470696
B1686: NO1.HM | D1686: Unable to collect data for the field 'TR.F.CashCashEquivTot' and some specific identifier(s).
B1687: PCH.HN | C1687: 43830 | D1687: 8596576399
B1688: PCH.HN | C1688: 44196 | D1688: 11885532811
B1689: PCH.HN | C1689: 44561 | D1689: 18490168292
B1690: PCH.HN | C1690: 44926 | D1690: 36690584484
B1691: PCH.HN | C1691: 45291 | D1691: 23916611263
B1692: PCH.HN | C1692: 45657 | D1692: 22777042455
B1693: DVM.HN | C1693: 44196 | D1693: 24308042720
B1694: DVM.HN | C1694: 44561 | D1694: 89871170714
B1695: DVM.HN | C1695: 44926 | D1695: 127602817725
...

Sheet NDFkOTAwZDQtYWUyNS00ZW
D3: AuditId=84075_107403491_STD_9BF32382-3105-42E3-862E-9A4D9DE0A102
D4: AuditId=82689_107403491_STD_9B7E228C-30CC-47A9-BF23-D89134DA4202
D5: AuditId=59561420_107403491_STD_B94F5566-D734-4E4D-B3F0-2114155A5E1C
D6: AuditId=59562402_107403491_STD_B94F5566-D734-4E4D-B3F0-2114155A5E1C
D7: AuditId=192616546_107403491_STD_6C81D584-74D2-4A8C-8F9B-51699DB4BAA3
D8: AuditId=192615196_107403491_STD_E565C324-8850-4FD0-B46D-2B9F69081D57
D9: AuditId=84910_107393580_STD_76DC990E-8B41-474E-80E2-19FA65173E0D
D10: AuditId=96554_107393580_STD_4584CB4A-AD7A-40A7-936A-AF5C3F599EBE
D11: AuditId=109496_107393580_STD_6C5750DE-DE26-45FE-B414-E983390575C6
D12: AuditId=119080_107393580_STD_8188729F-1D90-4755-A9D9-80055338A825
D13: AuditId=128577_107393580_STD_CBF8EFB9-56F4-444B-B436-B0CD02DCA05A
D14: AuditId=138146_107393580_STD_6B491C50-4574-46A5-AAB6-631899E467AB
... D4137: AuditId=2155_117098222_STD_B19BFE22-CAD3-466D-A384-948696FCA09A

Sheet Sheet23
A1: =_xll.RDP.Data(Sheet1!$A$2:$A$696,"TR.F.NetIncAfterTax","Period=FY0 Frq=FY SDate=#1 EDate=#2 CH=Fd RH=IN;periodenddate",B2,Sheet2!$A$1,Sheet2!$A$2) -> Updated at 14:40:03
D2: Net Income after Tax
B3: CHP.HM | C3: 43830 | D3: 216054818493
B4: CHP.HM | C4: 44196 | D4: 278372060882
B5: CHP.HM | C5: 44561 | D5: 242074622322
B6: CHP.HM | C6: 44926 | D6: 510295093778
B7: CHP.HM | C7: 45291 | D7: 336954868099
B8: CHP.HM | C8: 45657 | D8: 313767090621
B9: V21.HN | C9: 43830 | D9: 661264024
B10: V21.HN | C10: 44196 | D10: 1150350656
B11: V21.HN | C11: 44561 | D11: 3713924322
B12: V21.HN | C12: 44926 | D12: 928884788
B13: V21.HN | C13: 45291 | D13: 59007958
B14: V21.HN | C14: 45657 | D14: -1176066225
... B592: JVC.HM | C592: 44286 | D592: -76685819426
B593: JVC.HM | C593: 44926 | D593: NULL
B594: JVC.HM | C594: 44926 | D594: NULL
B595: JVC.HM | C595: 45291 | D595: 52639842397
B596: JVC.HM | C596: 45657 | D596: 40336096061
B597: PTB.HM | C597: 43830 | D597: 456802969520
B598: PTB.HM | C598: 44196 | D598: 379305449080
B599: PTB.HM | C599: 44561 | D599: 525894613782
B600: PTB.HM | C600: 44926 | D600: 502438563190
B601: PTB.HM | C601: 45291 | D601: 259467307655
B602: PTB.HM | C602: 45657 | D602: 376311422056
B603: CIG.HM | C603: 43830 | D603: 125278920
B604: CIG.HM | C604: 44196 | D604: -174896569573
B605: CIG.HM | C605: 44561 | D605: 16548612398
B606: CIG.HM | C606: 44926 | D606: -6656969478
... B1685: ICT.HM | C1685: 45657 | D1685: 31104257416
B1686: NO1.HM | D1686: Unable to collect data for the field 'TR.F.NetIncAfterTax' and some specific identifier(s).
B1687: PCH.HN | C1687: 43830 | D1687: 6184561318
B1688: PCH.HN | C1688: 44196 | D1688: 12003756395
B1689: PCH.HN | C1689: 44561 | D1689: 12551310756
B1690: PCH.HN | C1690: 44926 | D1690: 14183284394
B1691: PCH.HN | C1691: 45291 | D1691: 12297857776
B1692: PCH.HN | C1692: 45657 | D1692: 12857134636
B1693: DVM.HN | C1693: 44196 | D1693: 21523631183
B1694: DVM.HN | C1694: 44561 | D1694: 50140891761
B1695: DVM.HN | C1695: 44926 | D1695: 54415230945
...

Sheet ZjUxOWE2N2ItNTRjYi00Nm
D3: AuditId=84059_107403491_STD_9BF32382-3105-42E3-862E-9A4D9DE0A102
D4: AuditId=82676_107403491_STD_9B7E228C-30CC-47A9-BF23-D89134DA4202
D5: AuditId=59561400_107403491_STD_B94F5566-D734-4E4D-B3F0-2114155A5E1C
D6: AuditId=59562385_107403491_STD_B94F5566-D734-4E4D-B3F0-2114155A5E1C
D7: AuditId=192616531_107403491_STD_6C81D584-74D2-4A8C-8F9B-51699DB4BAA3
D8: AuditId=192615183_107403491_STD_E565C324-8850-4FD0-B46D-2B9F69081D57
D9: AuditId=84894_107393580_STD_76DC990E-8B41-474E-80E2-19FA65173E0D
D10: AuditId=96543_107393580_STD_4584CB4A-AD7A-40A7-936A-AF5C3F599EBE
D11: AuditId=109476_107393580_STD_6C5750DE-DE26-45FE-B414-E983390575C6
D12: AuditId=119061_107393580_STD_8188729F-1D90-4755-A9D9-80055338A825
D13: AuditId=128562_107393580_STD_CBF8EFB9-56F4-444B-B436-B0CD02DCA05A
D14: AuditId=138130_107393580_STD_6B491C50-4574-46A5-AAB6-631899E467AB
... D4137: AuditId=2135_117098222_STD_B19BFE22-CAD3-466D-A384-948696FCA09A

Sheet Sheet25
A1: =_xll.RDP.Data(Sheet1!$A$2:$A$696,"TR.F.TotRevenue","Period=FY0 Frq=FY SDate=#1 EDate=#2 CH=Fd RH=IN;periodenddate",B2,Sheet2!$A$1,Sheet2!$A$2) -> Updated at 14:44:32
D2: Revenue from Business Activities - Total
B3: CHP.HM | C3: 43830 | D3: 713535772923
B4: CHP.HM | C4: 44196 | D4: 830524857602
B5: CHP.HM | C5: 44561 | D5: 787447457857
B6: CHP.HM | C6: 44926 | D6: 1100534048069
B7: CHP.HM | C7: 45291 | D7: 881377927945
B8: CHP.HM | C8: 45657 | D8: 814199531520
B9: V21.HN | C9: 43830 | D9: 378114031343
B10: V21.HN | C10: 44196 | D10: 162752725227
B11: V21.HN | C11: 44561 | D11: 125499975935
B12: V21.HN | C12: 44926 | D12: 61220235368
B13: V21.HN | C13: 45291 | D13: 107609657162
B14: V21.HN | C14: 45657 | D14: 119230524183
... B592: JVC.HM | C592: 44286 | D592: 411416951706
B593: JVC.HM | C593: 44926 | D593: NULL
B594: JVC.HM | C594: 44926 | D594: NULL
B595: JVC.HM | C595: 45291 | D595: 576287155805
B596: JVC.HM | C596: 45657 | D596: 611540459301
B597: PTB.HM | C597: 43830 | D597: 5549137355104
B598: PTB.HM | C598: 44196 | D598: 5601236769697
B599: PTB.HM | C599: 44561 | D599: 6491949040731
B600: PTB.HM | C600: 44926 | D600: 6886522253734
B601: PTB.HM | C601: 45291 | D601: 5618569890239
B602: PTB.HM | C602: 45657 | D602: 6466470034276
B603: CIG.HM | C603: 43830 | D603: 2589213336
B604: CIG.HM | C604: 44196 | D604: 25610385676
B605: CIG.HM | C605: 44561 | D605: 29583834844
B606: CIG.HM | C606: 44926 | D606: 83224739215
... B1685: ICT.HM | C1685: 45657 | D1685: 1572511299308
B1686: NO1.HM | D1686: Unable to collect data for the field 'TR.F.TotRevenue' and some specific identifier(s).
B1687: PCH.HN | C1687: 43830 | D1687: 115018059644
B1688: PCH.HN | C1688: 44196 | D1688: 128910028821
B1689: PCH.HN | C1689: 44561 | D1689: 125604903978
B1690: PCH.HN | C1690: 44926 | D1690: 151962809609
B1691: PCH.HN | C1691: 45291 | D1691: 124650435594
B1692: PCH.HN | C1692: 45657 | D1692: 194942239067
B1693: DVM.HN | C1693: 44196 | D1693: 842716225965
B1694: DVM.HN | C1694: 44561 | D1694: 1048919705587
B1695: DVM.HN | C1695: 44926 | D1695: 1178951172555
...

Sheet Sheet27
A1: =_xll.RDP.Data(Sheet1!$A$2:$A$696,"TR.F.IncBefTax","Period=FY0 Frq=FY SDate=#1 EDate=#2 CH=Fd RH=IN;periodenddate",B2,Sheet2!$A$1,Sheet2!$A$2) -> Updated at 14:45:53
D2: Income before Taxes
B3: CHP.HM | C3: 43830 | D3: 226713780181
B4: CHP.HM | C4: 44196 | D4: 290832743157
B5: CHP.HM | C5: 44561 | D5: 254492336625
B6: CHP.HM | C6: 44926 | D6: 535957349060
B7: CHP.HM | C7: 45291 | D7: 355431626080
B8: CHP.HM | C8: 45657 | D8: 331962474374
B9: V21.HN | C9: 43830 | D9: 2377163766
B10: V21.HN | C10: 44196 | D10: 1590539789
B11: V21.HN | C11: 44561 | D11: 3713924322
B12: V21.HN | C12: 44926 | D12: 928884788
B13: V21.HN | C13: 45291 | D13: 402036526
B14: V21.HN | C14: 45657 | D14: -1176066225
... B592: JVC.HM | C592: 44286 | D592: -76578967464
B593: JVC.HM | C593: 44926 | D593: NULL
B594: JVC.HM | C594: 44926 | D594: NULL
B595: JVC.HM | C595: 45291 | D595: 55924271928
B596: JVC.HM | C596: 45657 | D596: 58865008889
B597: PTB.HM | C597: 43830 | D597: 550035460492
B598: PTB.HM | C598: 44196 | D598: 462307957661
B599: PTB.HM | C599: 44561 | D599: 650493184310
B600: PTB.HM | C600: 44926 | D600: 613995640567
B601: PTB.HM | C601: 45291 | D601: 322753317301
B602: PTB.HM | C602: 45657 | D602: 471981832117
B603: CIG.HM | C603: 43830 | D603: 1208542024
B604: CIG.HM | C604: 44196 | D604: -174896569573
B605: CIG.HM | C605: 44561 | D605: 16552136016
B606: CIG.HM | C606: 44926 | D606: -6631291648
... B1685: ICT.HM | C1685: 45657 | D1685: 37182705522
B1686: NO1.HM | D1686: Unable to collect data for the field 'TR.F.IncBefTax' and some specific identifier(s).
B1687: PCH.HN | C1687: 43830 | D1687: 7743372206
B1688: PCH.HN | C1688: 44196 | D1688: 14317878476
B1689: PCH.HN | C1689: 44561 | D1689: 14957263959
B1690: PCH.HN | C1690: 44926 | D1690: 18103971424
B1691: PCH.HN | C1691: 45291 | D1691: 15033082796
B1692: PCH.HN | C1692: 45657 | D1692: 17314275712
B1693: DVM.HN | C1693: 44196 | D1693: 24338397450
B1694: DVM.HN | C1694: 44561 | D1694: 54446873583
B1695: DVM.HN | C1695: 44926 | D1695: 63703061248
...

Sheet MThkOGYxZGEtYzk1ZC00MT
D3: AuditId=84072_107403491_STD_9BF32382-3105-42E3-862E-9A4D9DE0A102
D4: AuditId=82686_107403491_STD_9B7E228C-30CC-47A9-BF23-D89134DA4202
D5: AuditId=59561413_107403491_STD_B94F5566-D734-4E4D-B3F0-2114155A5E1C
D6: AuditId=59562399_107403491_STD_B94F5566-D734-4E4D-B3F0-2114155A5E1C
D7: AuditId=192616543_107403491_STD_6C81D584-74D2-4A8C-8F9B-51699DB4BAA3
D8: AuditId=192615193_107403491_STD_E565C324-8850-4FD0-B46D-2B9F69081D57
D9: AuditId=84906_107393580_STD_76DC990E-8B41-474E-80E2-19FA65173E0D
D10: AuditId=96553_107393580_STD_4584CB4A-AD7A-40A7-936A-AF5C3F599EBE
D11: AuditId=109489_107393580_STD_6C5750DE-DE26-45FE-B414-E983390575C6
D12: AuditId=119075_107393580_STD_8188729F-1D90-4755-A9D9-80055338A825
D13: AuditId=128572_107393580_STD_CBF8EFB9-56F4-444B-B436-B0CD02DCA05A
D14: AuditId=138141_107393580_STD_6B491C50-4574-46A5-AAB6-631899E467AB
... D4137: AuditId=2148_117098222_STD_B19BFE22-CAD3-466D-A384-948696FCA09A

Sheet ZjM4ZmM2NmMtNDY1ZS00ZT
D3: AuditId=84075_107403491_STD_9BF32382-3105-42E3-862E-9A4D9DE0A102
D4: AuditId=82689_107403491_STD_9B7E228C-30CC-47A9-BF23-D89134DA4202
D5: AuditId=59561420_107403491_STD_B94F5566-D734-4E4D-B3F0-2114155A5E1C
D6: AuditId=59562402_107403491_STD_B94F5566-D734-4E4D-B3F0-2114155A5E1C
D7: AuditId=192616546_107403491_STD_6C81D584-74D2-4A8C-8F9B-51699DB4BAA3
D8: AuditId=192615196_107403491_STD_E565C324-8850-4FD0-B46D-2B9F69081D57
D9: AuditId=84910_107393580_STD_76DC990E-8B41-474E-80E2-19FA65173E0D
D10: AuditId=96554_107393580_STD_4584CB4A-AD7A-40A7-936A-AF5C3F599EBE
D11: AuditId=109496_107393580_STD_6C5750DE-DE26-45FE-B414-E983390575C6
D12: AuditId=119080_107393580_STD_8188729F-1D90-4755-A9D9-80055338A825
D13: AuditId=128577_107393580_STD_CBF8EFB9-56F4-444B-B436-B0CD02DCA05A
D14: AuditId=138146_107393580_STD_6B491C50-4574-46A5-AAB6-631899E467AB
... D4137: AuditId=2155_117098222_STD_B19BFE22-CAD3-466D-A384-948696FCA09A

Sheet YmFlYWM4NmItZDc4NS00ZT
D3: AuditId=83979_107403491_STD_9BF32382-3105-42E3-862E-9A4D9DE0A102
D4: AuditId=82622_107403491_STD_9B7E228C-30CC-47A9-BF23-D89134DA4202
D5: AuditId=59561293_107403491_STD_B94F5566-D734-4E4D-B3F0-2114155A5E1C
D6: AuditId=59562312_107403491_STD_B94F5566-D734-4E4D-B3F0-2114155A5E1C
D7: AuditId=192616459_107403491_STD_6C81D584-74D2-4A8C-8F9B-51699DB4BAA3
D8: AuditId=192615130_107403491_STD_E565C324-8850-4FD0-B46D-2B9F69081D57
D10: AuditId=87388_107345512_STD_7B8F1745-6942-46B4-BA25-8101F8D58C43
D11: AuditId=100576_107345512_STD_10E5FD24-B4A6-466A-8B7F-8FDBDD7A2CDA
D12: AuditId=115496_107345512_STD_5765C885-696A-4BB0-8345-B5D1C83BDED9
D13: AuditId=126248_107345512_STD_C5C6F882-0625-4D02-8D51-B637A286169C
D14: AuditId=149931_107345512_STD_108A8818-44A6-46C9-8EEB-4DFE5ED8CAE2
D15: AuditId=148453_107345512_STD_740CA875-3E53-498F-B93C-9A2072BC6A88
... D3248: AuditId=2063_117098222_STD_B19BFE22-CAD3-466D-A384-948696FCA09A

Sheet Sheet28
A1: =_xll.RDP.Data(Sheet1!$A$2:$A$696,"TR.F.NetIncAfterTax","Period=FY0 Frq=FY SDate=#1 EDate=#2 CH=Fd RH=IN;periodenddate",B2,Sheet2!$A$1,Sheet2!$A$2) -> Updated at 14:49:16
D2: Net Income after Tax
B3: CHP.HM | C3: 43830 | D3: 216054818493
B4: CHP.HM | C4: 44196 | D4: 278372060882
B5: CHP.HM | C5: 44561 | D5: 242074622322
B6: CHP.HM | C6: 44926 | D6: 510295093778
B7: CHP.HM | C7: 45291 | D7: 336954868099
B8: CHP.HM | C8: 45657 | D8: 313767090621
B9: V21.HN | C9: 43830 | D9: 661264024
B10: V21.HN | C10: 44196 | D10: 1150350656
B11: V21.HN | C11: 44561 | D11: 3713924322
B12: V21.HN | C12: 44926 | D12: 928884788
B13: V21.HN | C13: 45291 | D13: 59007958
B14: V21.HN | C14: 45657 | D14: -1176066225
... B592: JVC.HM | C592: 44286 | D592: -76685819426
B593: JVC.HM | C593: 44926 | D593: NULL
B594: JVC.HM | C594: 44926 | D594: NULL
B595: JVC.HM | C595: 45291 | D595: 52639842397
B596: JVC.HM | C596: 45657 | D596: 40336096061
B597: PTB.HM | C597: 43830 | D597: 456802969520
B598: PTB.HM | C598: 44196 | D598: 379305449080
B599: PTB.HM | C599: 44561 | D599: 525894613782
B600: PTB.HM | C600: 44926 | D600: 502438563190
B601: PTB.HM | C601: 45291 | D601: 259467307655
B602: PTB.HM | C602: 45657 | D602: 376311422056
B603: CIG.HM | C603: 43830 | D603: 125278920
B604: CIG.HM | C604: 44196 | D604: -174896569573
B605: CIG.HM | C605: 44561 | D605: 16548612398
B606: CIG.HM | C606: 44926 | D606: -6656969478
... B1685: ICT.HM | C1685: 45657 | D1685: 31104257416
B1686: NO1.HM | D1686: Unable to collect data for the field 'TR.F.NetIncAfterTax' and some specific identifier(s).
B1687: PCH.HN | C1687: 43830 | D1687: 6184561318
B1688: PCH.HN | C1688: 44196 | D1688: 12003756395
B1689: PCH.HN | C1689: 44561 | D1689: 12551310756
B1690: PCH.HN | C1690: 44926 | D1690: 14183284394
B1691: PCH.HN | C1691: 45291 | D1691: 12297857776
B1692: PCH.HN | C1692: 45657 | D1692: 12857134636
B1693: DVM.HN | C1693: 44196 | D1693: 21523631183
B1694: DVM.HN | C1694: 44561 | D1694: 50140891761
B1695: DVM.HN | C1695: 44926 | D1695: 54415230945
...

Sheet Sheet31
A1: =_xll.RDP.Data(Sheet1!$A$2:$A$696,"TR.F.GrossTotRevBizActiv","Period=FY0 Frq=FY SDate=#1 EDate=#2 CH=Fd RH=IN;periodenddate",B2,Sheet2!$A$1,Sheet2!$A$2) -> Updated at 14:47:58
D2: Gross Revenue from Business Activities - Total
B3: CHP.HM | C3: 43830 | D3: 713535772923
B4: CHP.HM | C4: 44196 | D4: 830524857602
B5: CHP.HM | C5: 44561 | D5: 787447457857
B6: CHP.HM | C6: 44926 | D6: 1100534048069
B7: CHP.HM | C7: 45291 | D7: 881377927945
B8: CHP.HM | C8: 45657 | D8: 814199531520
B9: V21.HN | D9: NULL
B10: LIG.HN | C10: 43830 | D10: 2228795106735
B11: LIG.HN | C11: 44196 | D11: 2341590275188
B12: LIG.HN | C12: 44561 | D12: 2439778222621
B13: LIG.HN | C13: 44926 | D13: 2968797065446
B14: LIG.HN | C14: 45291 | D14: 3325201927581
B15: LIG.HN | C15: 45657 | D15: 3695151811446
B16: MCC.HN | D16: NULL
B17: TET.HN | C17: 43830 | D17: 24854514818
B18: TET.HN | C18: 44196 | D18: 22682602637
B19: TET.HN | C19: 44561 | D19: 22593129147
B20: TET.HN | C20: 44926 | D20: 22997604620
B21: TET.HN | C21: 45291 | D21: 23988586386
B22: TET.HN | C22: 45657 | D22: 23541850564
B23: KSD.HN | C23: 43830 | D23: 105196797937
B24: KSD.HN | C24: 44196 | D24: 12162171254
B25: KSD.HN | C25: 44561 | D25: 68826576091
B26: KSD.HN | C26: 44926 | D26: 102955130039
B27: KSD.HN | C27: 45291 | D27: 52357797331
B28: KSD.HN | C28: 45657 | D28: 47136727334
... B58: NVT.HM | C58: 45657 | D58: 410702451708
B59: VCM.HN | D59: NULL
B60: SPM.HM | C60: 43830 | D60: 555755824664
B61: SPM.HM | C61: 44196 | D61: 660069034058
B62: SPM.HM | C62: 44561 | D62: 768359616822
B63: SPM.HM | C63: 44926 | D63: 771276505025
B64: SPM.HM | C64: 45291 | D64: 461031858201
B65: SPM.HM | C65: 45657 | D65: 348984734523
B66: CX8.HN | D66: NULL
B67: TNT.HM | C67: 43830 | D67: 176314537729
B68: TNT.HM | C68: 44196 | D68: 12866920534
B69: TNT.HM | C69: 44561 | D69: 640949396541
...

Sheet MDBkNTA5MzMtODI4ZS00ND
D3: AuditId=84059_107403491_STD_9BF32382-3105-42E3-862E-9A4D9DE0A102
D4: AuditId=82676_107403491_STD_9B7E228C-30CC-47A9-BF23-D89134DA4202
D5: AuditId=59561400_107403491_STD_B94F5566-D734-4E4D-B3F0-2114155A5E1C
D6: AuditId=59562385_107403491_STD_B94F5566-D734-4E4D-B3F0-2114155A5E1C
D7: AuditId=192616531_107403491_STD_6C81D584-74D2-4A8C-8F9B-51699DB4BAA3
D8: AuditId=192615183_107403491_STD_E565C324-8850-4FD0-B46D-2B9F69081D57
D9: AuditId=84894_107393580_STD_76DC990E-8B41-474E-80E2-19FA65173E0D
D10: AuditId=96543_107393580_STD_4584CB4A-AD7A-40A7-936A-AF5C3F599EBE
D11: AuditId=109476_107393580_STD_6C5750DE-DE26-45FE-B414-E983390575C6
D12: AuditId=119061_107393580_STD_8188729F-1D90-4755-A9D9-80055338A825
D13: AuditId=128562_107393580_STD_CBF8EFB9-56F4-444B-B436-B0CD02DCA05A
D14: AuditId=138130_107393580_STD_6B491C50-4574-46A5-AAB6-631899E467AB
... D4137: AuditId=2135_117098222_STD_B19BFE22-CAD3-466D-A384-948696FCA09A

Sheet Sheet33
A1: =_xll.RDP.Data(Sheet1!$A$2:$A$696,"TR.F.TotRevenue","Period=FY0 Frq=FY SDate=#1 EDate=#2 CH=Fd RH=IN;periodenddate",B2,Sheet2!$A$1,Sheet2!$A$2) -> Updated at 14:49:47
D2: Revenue from Business Activities - Total
B3: CHP.HM | C3: 43830 | D3: 713535772923
B4: CHP.HM | C4: 44196 | D4: 830524857602
B5: CHP.HM | C5: 44561 | D5: 787447457857
B6: CHP.HM | C6: 44926 | D6: 1100534048069
B7: CHP.HM | C7: 45291 | D7: 881377927945
B8: CHP.HM | C8: 45657 | D8: 814199531520
B9: V21.HN | C9: 43830 | D9: 378114031343
B10: V21.HN | C10: 44196 | D10: 162752725227
B11: V21.HN | C11: 44561 | D11: 125499975935
B12: V21.HN | C12: 44926 | D12: 61220235368
B13: V21.HN | C13: 45291 | D13: 107609657162
B14: V21.HN | C14: 45657 | D14: 119230524183
... B592: JVC.HM | C592: 44286 | D592: 411416951706
B593: JVC.HM | C593: 44926 | D593: NULL
B594: JVC.HM | C594: 44926 | D594: NULL
B595: JVC.HM | C595: 45291 | D595: 576287155805
B596: JVC.HM | C596: 45657 | D596: 611540459301
B597: PTB.HM | C597: 43830 | D597: 5549137355104
B598: PTB.HM | C598: 44196 | D598: 5601236769697
B599: PTB.HM | C599: 44561 | D599: 6491949040731
B600: PTB.HM | C600: 44926 | D600: 6886522253734
B601: PTB.HM | C601: 45291 | D601: 5618569890239
B602: PTB.HM | C602: 45657 | D602: 6466470034276
B603: CIG.HM | C603: 43830 | D603: 2589213336
B604: CIG.HM | C604: 44196 | D604: 25610385676
B605: CIG.HM | C605: 44561 | D605: 29583834844
B606: CIG.HM | C606: 44926 | D606: 83224739215
... B1685: ICT.HM | C1685: 45657 | D1685: 1572511299308
B1686: NO1.HM | D1686: Unable to collect data for the field 'TR.F.TotRevenue' and some specific identifier(s).
B1687: PCH.HN | C1687: 43830 | D1687: 115018059644
B1688: PCH.HN | C1688: 44196 | D1688: 128910028821
B1689: PCH.HN | C1689: 44561 | D1689: 125604903978
B1690: PCH.HN | C1690: 44926 | D1690: 151962809609
B1691: PCH.HN | C1691: 45291 | D1691: 124650435594
B1692: PCH.HN | C1692: 45657 | D1692: 194942239067
B1693: DVM.HN | C1693: 44196 | D1693: 842716225965
B1694: DVM.HN | C1694: 44561 | D1694: 1048919705587
B1695: DVM.HN | C1695: 44926 | D1695: 1178951172555
...

Sheet NTg3YTE1N2UtYzkzNy00Y2
D3: AuditId=56701_107403491_ANA_E92228B8-0296-4287-8DDD-5E0328BE46A0
D4: AuditId=70842_107403491_ANA_E92228B8-0296-4287-8DDD-5E0328BE46A0
D5: AuditId=82335_107403491_ANA_AFDAFB28-45F9-4151-951E-ABE96B778760
D6: AuditId=90527_107403491_ANA_AFDAFB28-45F9-4151-951E-ABE96B778760
D7: AuditId=98150_107403491_ANA_00985E94-2192-4CD7-B18B-C0BCBD380369
D8: AuditId=108009_107403491_ANA_00985E94-2192-4CD7-B18B-C0BCBD380369
D9: AuditId=72909_107393580_ANA_D46F9705-52F6-414B-AEC5-FB9D2C7F6DC6
D10: AuditId=87317_107393580_ANA_240465D7-8DCF-4CB9-BF22-788C97BDD91B
D11: AuditId=102459_107393580_ANA_26BE7B93-4FA1-44AD-AB3B-ABFAA9A2B8AB
D12: AuditId=110749_107393580_ANA_D66A0492-3156-444D-9561-842B5A661E74
D13: AuditId=120230_107393580_ANA_6DC35B26-5A22-4FF9-B3C0-933FF3C62F1E
D15: AuditId=74783_107345512_ANA_2F2CD24E-5C3E-4560-853D-D92B0549FC5E
... D4130: AuditId=2982_117098222_ANA_30967E00-462D-4CB7-99E6-F624516FC6B0

Sheet Sheet36
A1: =_xll.RDP.Data(Sheet1!$A$2:$A$696,"TR.InvtrDivPayoutRatio","Period=FY0 Frq=FY SDate=#1 EDate=#2 CH=Fd RH=IN;periodenddate",B2,Sheet2!$A$1,Sheet2!$A$2) -> Updated at 14:52:18
A2: =_xll.RDP.Data(Sheet1!$A$2:$A$696,"TR.F.DivPayoutRatioPct","Period=FY0 Frq=FY SDate=#1 EDate=#2 CH=Fd RH=IN;periodenddate",B2,Sheet2!$A$1,Sheet2!$A$2) -> Updated at 14:53:17 | D2: Dividend Payout Ratio - %
B3: CHP.HM | C3: 43830 | D3: 100.97014
B4: CHP.HM | C4: 44196 | D4: 49.788942
B5: CHP.HM | C5: 44561 | D5: 101.56997
B6: CHP.HM | C6: 44926 | D6: 34.547697
B7: CHP.HM | C7: 45291 | D7: 118.50852
B8: CHP.HM | C8: 45657 | D8: 79.597747
B9: V21.HN | C9: 43830 | D9: 0
B10: V21.HN | C10: 44196 | D10: 0
B11: V21.HN | C11: 44561 | D11: 0
B12: V21.HN | C12: 44926 | D12: 0
B13: V21.HN | C13: 45291 | D13: 0
B14: V21.HN | C14: 45657 | D14: NULL
B15: LIG.HN | C15: 43830 | D15: 134.1026
B16: LIG.HN | C16: 44196 | D16: 0
B17: LIG.HN | C17: 44561 | D17: 0
B18: LIG.HN | C18: 44926 | D18: 0
B19: LIG.HN | C19: 45291 | D19: NULL
B20: LIG.HN | C20: 45657 | D20: 0
B21: MCC.HN | C21: 43830 | D21: 87.268959
B22: MCC.HN | C22: 44196 | D22: 157.91891
B23: MCC.HN | C23: 44561 | D23: 103.24029
B24: MCC.HN | C24: 44926 | D24: 54.238347
B25: MCC.HN | C25: 45291 | D25: 1781.3407
B26: MCC.HN | C26: 45657 | D26: 0
B27: TET.HN | C27: 43830 | D27: 102.55643
B28: TET.HN | C28: 44196 | D28: 40.413657
B29: TET.HN | C29: 44561 | D29: 30.174714
B30: TET.HN | C30: 44926 | D30: 52.605395
B31: TET.HN | C31: 45291 | D31: 31.15469
... B33: KSD.HN | C33: 43830 | D33: 0
B34: KSD.HN | C34: 44196 | D34: NULL
B35: KSD.HN | C35: 44561 | D35: 0
B36: KSD.HN | C36: 44926 | D36: 6186.007
B37: KSD.HN | C37: 45291 | D37: 0
B38: KSD.HN | C38: 45657 | D38: NULL
B39: NBW.HN | C39: 43830 | D39: 64.260131
B40: NBW.HN | C40: 44196 | D40: 60.035945
B41: NBW.HN | C41: 44561 | D41: 65.565012
...

Sheet Sheet35
A1: =_xll.RDP.Data(Sheet1!$A$2:$A$696,"TR.TOTALNUMBEROFSHARESOUTSTANDING","Period=FY0 Frq=FY SDate=#1 EDate=#2 CH=Fd RH=IN;periodenddate",B2,Sheet2!$A$1,Sheet2!$A$2) -> Updated at 14:51:21
D2: Total Number of Shares Outstanding
B3: CHP.HM | D3: NULL
B4: V21.HN | D4: NULL
B5: LIG.HN | D5: NULL
B6: MCC.HN | D6: NULL
B7: TET.HN | D7: NULL
B8: KSD.HN | D8: NULL
B9: NBW.HN | D9: NULL
B10: TDC.HM | D10: NULL
B11: OGC.HM | D11: NULL
B12: HTC.HN | D12: NULL
B13: NVT.HM | D13: NULL
B14: VCM.HN | D14: NULL
... B697: TCX.HM | D697: NULL

Sheet Sheet38
A1: =_xll.RDP.Data(Sheet1!$A$2:$A$696,"TR.InvtrDivPayoutRatio","Period=FY0 Frq=FY SDate=#1 EDate=#2 CH=Fd RH=IN;periodenddate",B2,Sheet2!$A$1,Sheet2!$A$2) -> Updated at 14:55:37
A2: =_xll.RDP.Data(Sheet1!$A$2:$A$696,"TR.InvtrEPS5YearProjGr","Period=FY0 Frq=FY SDate=#1 EDate=#2 CH=Fd RH=IN;periodenddate",B2,Sheet2!$A$1,Sheet2!$A$2) -> Updated at 14:57:27 | B2: Output parameter 'PERIODENDDATE' is unrecognized. This could possibly happen because of mismatch between top level function expression and its usage in output. Make sure that you used exactly 1:1 identical expressions.
